2023-08-12 12:18:32,442 INFO    StreamThr :12565 [internal.py:wandb_internal():86] W&B internal server running at pid: 12565, started at: 2023-08-12 12:18:32.441807
2023-08-12 12:18:32,445 DEBUG   HandlerThread:12565 [handler.py:handle_request():144] handle_request: status
2023-08-12 12:18:32,449 INFO    WriterThread:12565 [datastore.py:open_for_write():85] open: /opt/ml/Facial_verification/wandb/run-20230812_121832-inoj3xyr/run-inoj3xyr.wandb
2023-08-12 12:18:32,450 DEBUG   SenderThread:12565 [sender.py:send():369] send: header
2023-08-12 12:18:32,464 DEBUG   SenderThread:12565 [sender.py:send():369] send: run
2023-08-12 12:18:32,842 ERROR   SenderThread:12565 [internal_api.py:execute():324] 401 response executing GraphQL.
2023-08-12 12:18:32,842 ERROR   SenderThread:12565 [internal_api.py:execute():325] {"errors":[{"message":"user is not logged in","path":["upsertBucket"],"extensions":{"code":"PERMISSION_ERROR"}}],"data":{"upsertBucket":null}}
2023-08-12 12:18:32,842 ERROR   SenderThread:12565 [sender.py:send_run():955] The API key you provided is either invalid or missing.  If the `WANDB_API_KEY` environment variable is set, make sure it is correct. Otherwise, to resolve this issue, you may try running the 'wandb login --relogin' command. If you are using a local server, make sure that you're using the correct hostname. If you're not sure, you can try logging in again using the 'wandb login --relogin --host [hostname]' command.(Error 401: Unauthorized)
Traceback (most recent call last):
  File "/opt/conda/envs/insight/lib/python3.8/site-packages/wandb/sdk/lib/retry.py", line 131, in __call__
    result = self._call_fn(*args, **kwargs)
  File "/opt/conda/envs/insight/lib/python3.8/site-packages/wandb/sdk/internal/internal_api.py", line 321, in execute
    return self.client.execute(*args, **kwargs)  # type: ignore
  File "/opt/conda/envs/insight/lib/python3.8/site-packages/wandb/vendor/gql-0.2.0/wandb_gql/client.py", line 52, in execute
    result = self._get_result(document, *args, **kwargs)
  File "/opt/conda/envs/insight/lib/python3.8/site-packages/wandb/vendor/gql-0.2.0/wandb_gql/client.py", line 60, in _get_result
    return self.transport.execute(document, *args, **kwargs)
  File "/opt/conda/envs/insight/lib/python3.8/site-packages/wandb/sdk/lib/gql_request.py", line 56, in execute
    request.raise_for_status()
  File "/opt/conda/envs/insight/lib/python3.8/site-packages/requests/models.py", line 1021, in raise_for_status
    raise HTTPError(http_error_msg, response=self)
requests.exceptions.HTTPError: 401 Client Error: Unauthorized for url: https://api.wandb.ai/graphql

During handling of the above exception, another exception occurred:

Traceback (most recent call last):
  File "/opt/conda/envs/insight/lib/python3.8/site-packages/wandb/sdk/internal/sender.py", line 953, in send_run
    self._init_run(run, config_value_dict)
  File "/opt/conda/envs/insight/lib/python3.8/site-packages/wandb/sdk/internal/sender.py", line 991, in _init_run
    server_run, inserted, server_messages = self._api.upsert_run(
  File "/opt/conda/envs/insight/lib/python3.8/site-packages/wandb/apis/normalize.py", line 73, in wrapper
    raise err
  File "/opt/conda/envs/insight/lib/python3.8/site-packages/wandb/apis/normalize.py", line 41, in wrapper
    return func(*args, **kwargs)
  File "/opt/conda/envs/insight/lib/python3.8/site-packages/wandb/sdk/internal/internal_api.py", line 1822, in upsert_run
    response = self.gql(
  File "/opt/conda/envs/insight/lib/python3.8/site-packages/wandb/sdk/internal/internal_api.py", line 293, in gql
    ret = self._retry_gql(
  File "/opt/conda/envs/insight/lib/python3.8/site-packages/wandb/sdk/lib/retry.py", line 147, in __call__
    retry_timedelta_triggered = check_retry_fn(e)
  File "/opt/conda/envs/insight/lib/python3.8/site-packages/wandb/util.py", line 946, in check_retry_fn
    return fallback_retry_fn(e)
  File "/opt/conda/envs/insight/lib/python3.8/site-packages/wandb/util.py", line 877, in no_retry_auth
    raise AuthenticationError(
wandb.errors.AuthenticationError: The API key you provided is either invalid or missing.  If the `WANDB_API_KEY` environment variable is set, make sure it is correct. Otherwise, to resolve this issue, you may try running the 'wandb login --relogin' command. If you are using a local server, make sure that you're using the correct hostname. If you're not sure, you can try logging in again using the 'wandb login --relogin --host [hostname]' command.(Error 401: Unauthorized)
2023-08-12 12:18:32,948 DEBUG   HandlerThread:12565 [handler.py:handle_request():144] handle_request: shutdown
2023-08-12 12:18:32,949 INFO    HandlerThread:12565 [handler.py:finish():854] shutting down handler
2023-08-12 12:18:33,464 INFO    WriterThread:12565 [datastore.py:close():298] close: /opt/ml/Facial_verification/wandb/run-20230812_121832-inoj3xyr/run-inoj3xyr.wandb
2023-08-12 12:18:33,845 INFO    SenderThread:12565 [sender.py:finish():1526] shutting down sender
